2023-02-07 10:24:56 AM - Error: The file config.yaml could not be found. <module> - FileNotFoundError(2, 'No such file or directory')
Traceback (most recent call last):
  File "/home/joaosilva/Documents/GitHub/Binance-Trader/Dev/Main.py", line 85, in <module>
    with open("config.yaml", "r") as file:
FileNotFoundError: [Errno 2] No such file or directory: 'config.yaml'
2023-02-07 10:25:00 AM - send_telegram_message - An Http Error occurred:HTTPError('400 Client Error: Bad Request for url: https://api.telegram.org/bot5889130031:AAHuojesIxu8m1NYCcSUW9kBVg1iKKfUkVU/sendMessage?chat_id=1144450791&text=%3Cpre%3E%E2%9A%A0+Error%3A+The+file+config.yaml+could+not+be+found.+%3Cmodule%3E+-+FileNotFoundError%282%2C+%27No+such+file+or+directory%27%29%3C%2Fpre%3E&parse_mode=HTML')
Traceback (most recent call last):
  File "/home/joaosilva/Documents/GitHub/Binance-Trader/Dev/Main.py", line 85, in <module>
    with open("config.yaml", "r") as file:
FileNotFoundError: [Errno 2] No such file or directory: 'config.yaml'

During handling of the above exception, another exception occurred:

Traceback (most recent call last):
  File "/home/joaosilva/Documents/GitHub/Binance-Trader/Dev/telegram.py", line 129, in send_telegram_message
    resp.raise_for_status()
  File "/home/joaosilva/.local/lib/python3.10/site-packages/requests/models.py", line 1021, in raise_for_status
    raise HTTPError(http_error_msg, response=self)
requests.exceptions.HTTPError: 400 Client Error: Bad Request for url: https://api.telegram.org/bot5889130031:AAHuojesIxu8m1NYCcSUW9kBVg1iKKfUkVU/sendMessage?chat_id=1144450791&text=%3Cpre%3E%E2%9A%A0+Error%3A+The+file+config.yaml+could+not+be+found.+%3Cmodule%3E+-+FileNotFoundError%282%2C+%27No+such+file+or+directory%27%29%3C%2Fpre%3E&parse_mode=HTML
2023-02-07 01:43:44 PM - Error: The file config.yaml could not be found. <module> - FileNotFoundError(2, 'No such file or directory')
Traceback (most recent call last):
  File "/home/joaosilva/Documents/GitHub/Binance-Trader/Dev/coinpairByMarketPhase.py", line 38, in <module>
    with open("config.yaml", "r") as file:
FileNotFoundError: [Errno 2] No such file or directory: 'config.yaml'
2023-02-07 01:43:45 PM - send_telegram_message - An Http Error occurred:HTTPError('400 Client Error: Bad Request for url: https://api.telegram.org/bot5889130031:AAHuojesIxu8m1NYCcSUW9kBVg1iKKfUkVU/sendMessage?chat_id=1144450791&text=%3Cpre%3E%E2%9A%A0+Error%3A+The+file+config.yaml+could+not+be+found.+%3Cmodule%3E+-+FileNotFoundError%282%2C+%27No+such+file+or+directory%27%29%3C%2Fpre%3E&parse_mode=HTML')
Traceback (most recent call last):
  File "/home/joaosilva/Documents/GitHub/Binance-Trader/Dev/coinpairByMarketPhase.py", line 38, in <module>
    with open("config.yaml", "r") as file:
FileNotFoundError: [Errno 2] No such file or directory: 'config.yaml'

During handling of the above exception, another exception occurred:

Traceback (most recent call last):
  File "/home/joaosilva/Documents/GitHub/Binance-Trader/Dev/telegram.py", line 129, in send_telegram_message
    resp.raise_for_status()
  File "/home/joaosilva/.local/lib/python3.10/site-packages/requests/models.py", line 1021, in raise_for_status
    raise HTTPError(http_error_msg, response=self)
requests.exceptions.HTTPError: 400 Client Error: Bad Request for url: https://api.telegram.org/bot5889130031:AAHuojesIxu8m1NYCcSUW9kBVg1iKKfUkVU/sendMessage?chat_id=1144450791&text=%3Cpre%3E%E2%9A%A0+Error%3A+The+file+config.yaml+could+not+be+found.+%3Cmodule%3E+-+FileNotFoundError%282%2C+%27No+such+file+or+directory%27%29%3C%2Fpre%3E&parse_mode=HTML
2023-02-08 12:15:12 PM - main - positions1d.csv - NameError("name 'get_strength' is not defined")
Traceback (most recent call last):
  File "/home/joaosilva/Documents/GitHub/Binance-Trader/Dev/addCoinPair.py", line 162, in main
    get_strength(symbol)
NameError: name 'get_strength' is not defined
2023-02-08 12:21:36 PM - main - positions1h.csv - NameError("name 'get_strength' is not defined")
Traceback (most recent call last):
  File "/home/joaosilva/Documents/GitHub/Binance-Trader/Dev/addCoinPair.py", line 162, in main
    get_strength(symbol)
NameError: name 'get_strength' is not defined
2023-02-08 12:22:05 PM - main - positions1d.csv - NameError("name 'get_strength' is not defined")
Traceback (most recent call last):
  File "/home/joaosilva/Documents/GitHub/Binance-Trader/Dev/addCoinPair.py", line 162, in main
    get_strength(symbol)
NameError: name 'get_strength' is not defined
2023-02-08 12:22:55 PM - addcoinpair - BrokenProcessPool('A process in the process pool was terminated abruptly while the future was running or pending.')
Traceback (most recent call last):
  File "/home/joaosilva/Documents/GitHub/Binance-Trader/Dev/BestEMA.py", line 274, in addcoinpair
    runBackTest(coinPair)
  File "/home/joaosilva/Documents/GitHub/Binance-Trader/Dev/BestEMA.py", line 205, in runBackTest
    stats, heatmap = bt.optimize(
  File "/home/joaosilva/.local/lib/python3.10/site-packages/backtesting/backtesting.py", line 1488, in optimize
    output = _optimize_grid()
  File "/home/joaosilva/.local/lib/python3.10/site-packages/backtesting/backtesting.py", line 1370, in _optimize_grid
    batch_index, values = future.result()
  File "/usr/lib/python3.10/concurrent/futures/_base.py", line 451, in result
    return self.__get_result()
  File "/usr/lib/python3.10/concurrent/futures/_base.py", line 403, in __get_result
    raise self._exception
concurrent.futures.process.BrokenProcessPool: A process in the process pool was terminated abruptly while the future was running or pending.
2023-02-08 02:51:06 PM - main - positions1h.csv - AttributeError("'numpy.int64' object has no attribute 'empty'")
Traceback (most recent call last):
  File "/home/joaosilva/Documents/GitHub/Binance-Trader/Dev/addCoinPair.py", line 185, in main
    rank = get_performance_rank(coinPair)
  File "/home/joaosilva/Documents/GitHub/Binance-Trader/Dev/addCoinPair.py", line 79, in get_performance_rank
    if res.empty:
AttributeError: 'numpy.int64' object has no attribute 'empty'
2023-02-08 02:52:38 PM - main - positions1d.csv - IndexError('index 0 is out of bounds for axis 0 with size 0')
Traceback (most recent call last):
  File "/home/joaosilva/Documents/GitHub/Binance-Trader/Dev/addCoinPair.py", line 185, in main
    rank = get_performance_rank(coinPair)
  File "/home/joaosilva/Documents/GitHub/Binance-Trader/Dev/addCoinPair.py", line 77, in get_performance_rank
    res = df.loc[df['Coinpair'] == symbol, 'performance_rank'].values[0]
IndexError: index 0 is out of bounds for axis 0 with size 0
2023-02-09 12:12:09 PM - runBackTest - coinpairBestEma.csv - FileNotFoundError(2, 'No such file or directory')
Traceback (most recent call last):
  File "/home/joaosilva/Documents/GitHub/Binance-Trader/Dev/BestEMA.py", line 229, in runBackTest
    coinpairBestEma = pd.read_csv(filename)
  File "/home/joaosilva/.local/lib/python3.10/site-packages/pandas/util/_decorators.py", line 211, in wrapper
    return func(*args, **kwargs)
  File "/home/joaosilva/.local/lib/python3.10/site-packages/pandas/util/_decorators.py", line 331, in wrapper
    return func(*args, **kwargs)
  File "/home/joaosilva/.local/lib/python3.10/site-packages/pandas/io/parsers/readers.py", line 950, in read_csv
    return _read(filepath_or_buffer, kwds)
  File "/home/joaosilva/.local/lib/python3.10/site-packages/pandas/io/parsers/readers.py", line 605, in _read
    parser = TextFileReader(filepath_or_buffer, **kwds)
  File "/home/joaosilva/.local/lib/python3.10/site-packages/pandas/io/parsers/readers.py", line 1442, in __init__
    self._engine = self._make_engine(f, self.engine)
  File "/home/joaosilva/.local/lib/python3.10/site-packages/pandas/io/parsers/readers.py", line 1735, in _make_engine
    self.handles = get_handle(
  File "/home/joaosilva/.local/lib/python3.10/site-packages/pandas/io/common.py", line 856, in get_handle
    handle = open(
FileNotFoundError: [Errno 2] No such file or directory: 'coinpairBestEma.csv'
2023-02-09 12:12:11 PM - main - coinpairBestEma.csv - FileNotFoundError(2, 'No such file or directory')
Traceback (most recent call last):
  File "/home/joaosilva/Documents/GitHub/Binance-Trader/Dev/addCoinPair.py", line 120, in main
    dfBestEMA = pd.read_csv(filename)
  File "/home/joaosilva/.local/lib/python3.10/site-packages/pandas/util/_decorators.py", line 211, in wrapper
    return func(*args, **kwargs)
  File "/home/joaosilva/.local/lib/python3.10/site-packages/pandas/util/_decorators.py", line 331, in wrapper
    return func(*args, **kwargs)
  File "/home/joaosilva/.local/lib/python3.10/site-packages/pandas/io/parsers/readers.py", line 950, in read_csv
    return _read(filepath_or_buffer, kwds)
  File "/home/joaosilva/.local/lib/python3.10/site-packages/pandas/io/parsers/readers.py", line 605, in _read
    parser = TextFileReader(filepath_or_buffer, **kwds)
  File "/home/joaosilva/.local/lib/python3.10/site-packages/pandas/io/parsers/readers.py", line 1442, in __init__
    self._engine = self._make_engine(f, self.engine)
  File "/home/joaosilva/.local/lib/python3.10/site-packages/pandas/io/parsers/readers.py", line 1735, in _make_engine
    self.handles = get_handle(
  File "/home/joaosilva/.local/lib/python3.10/site-packages/pandas/io/common.py", line 856, in get_handle
    handle = open(
FileNotFoundError: [Errno 2] No such file or directory: 'coinpairBestEma.csv'
